[2023-11-09 17:04:18,325] INFO _log() L224   * Restarting with stat - call_trace=C:\Users\talit\AppData\Local\Programs\Python\Python311\Lib\site-packages\werkzeug\_internal.py L224 
[2023-11-09 17:04:26,870] ERROR log_exception() L1449 Exception on /products [GET] - call_trace=C:\Users\talit\AppData\Local\Programs\Python\Python311\Lib\site-packages\flask\app.py L1449
Traceback (most recent call last):
  File "C:\Users\talit\AppData\Local\Programs\Python\Python311\Lib\site-packages\flask\app.py", line 2073, in wsgi_app
    response = self.full_dispatch_request()
               ^^^^^^^^^^^^^^^^^^^^^^^^^^^^
  File "C:\Users\talit\AppData\Local\Programs\Python\Python311\Lib\site-packages\flask\app.py", line 1519, in full_dispatch_request
    rv = self.handle_user_exception(e)
         ^^^^^^^^^^^^^^^^^^^^^^^^^^^^^
  File "C:\Users\talit\AppData\Local\Programs\Python\Python311\Lib\site-packages\flask_cors\extension.py", line 165, in wrapped_function
    return cors_after_request(app.make_response(f(*args, **kwargs)))
                                                ^^^^^^^^^^^^^^^^^^
  File "C:\Users\talit\AppData\Local\Programs\Python\Python311\Lib\site-packages\flask\app.py", line 1517, in full_dispatch_request
    rv = self.dispatch_request()
         ^^^^^^^^^^^^^^^^^^^^^^^
  File "C:\Users\talit\AppData\Local\Programs\Python\Python311\Lib\site-packages\flask\app.py", line 1503, in dispatch_request
    return self.ensure_sync(self.view_functions[rule.endpoint])(**req.view_args)
           ^^^^^^^^^^^^^^^^^^^^^^^^^^^^^^^^^^^^^^^^^^^^^^^^^^^^^^^^^^^^^^^^^^^^^
  File "C:\Users\talit\AppData\Local\Programs\Python\Python311\Lib\site-packages\flask_openapi3\scaffold.py", line 117, in view_func
    response = func(**func_kwargs)
               ^^^^^^^^^^^^^^^^^^^
  File "C:\fabrica\pessoal\pos-full-stack\mvp\first-sprint\back-end\app.py", line 82, in get_products
    products_representation = apresenta_products(products)
                              ^^^^^^^^^^^^^^^^^^^^^^^^^^^^
  File "C:\fabrica\pessoal\pos-full-stack\mvp\first-sprint\back-end\schemas\product.py", line 39, in apresenta_products
    "nome": product.nome,
            ^^^^^^^^^^^^
AttributeError: 'ellipsis' object has no attribute 'nome'
[2023-11-09 17:04:26,912] INFO _log() L224  127.0.0.1 - - [09/Nov/2023 17:04:26] "[35m[1mGET /products HTTP/1.1[0m" 500 - - call_trace=C:\Users\talit\AppData\Local\Programs\Python\Python311\Lib\site-packages\werkzeug\_internal.py L224 
[2023-11-09 17:06:13,152] INFO _log() L224   * Detected change in 'C:\\fabrica\\pessoal\\pos-full-stack\\mvp\\first-sprint\\back-end\\app.py', reloading - call_trace=C:\Users\talit\AppData\Local\Programs\Python\Python311\Lib\site-packages\werkzeug\_internal.py L224 
[2023-11-09 17:06:13,254] INFO _log() L224   * Restarting with stat - call_trace=C:\Users\talit\AppData\Local\Programs\Python\Python311\Lib\site-packages\werkzeug\_internal.py L224 
[2023-11-09 17:07:32,502] INFO _log() L224   * Detected change in 'C:\\fabrica\\pessoal\\pos-full-stack\\mvp\\first-sprint\\back-end\\app.py', reloading - call_trace=C:\Users\talit\AppData\Local\Programs\Python\Python311\Lib\site-packages\werkzeug\_internal.py L224 
[2023-11-09 17:07:32,618] INFO _log() L224   * Restarting with stat - call_trace=C:\Users\talit\AppData\Local\Programs\Python\Python311\Lib\site-packages\werkzeug\_internal.py L224 
[2023-11-09 17:07:43,102] INFO _log() L224   * Detected change in 'C:\\fabrica\\pessoal\\pos-full-stack\\mvp\\first-sprint\\back-end\\app.py', reloading - call_trace=C:\Users\talit\AppData\Local\Programs\Python\Python311\Lib\site-packages\werkzeug\_internal.py L224 
[2023-11-09 17:07:43,205] INFO _log() L224   * Restarting with stat - call_trace=C:\Users\talit\AppData\Local\Programs\Python\Python311\Lib\site-packages\werkzeug\_internal.py L224 
[2023-11-09 17:07:50,612] INFO _log() L224   * Detected change in 'C:\\fabrica\\pessoal\\pos-full-stack\\mvp\\first-sprint\\back-end\\app.py', reloading - call_trace=C:\Users\talit\AppData\Local\Programs\Python\Python311\Lib\site-packages\werkzeug\_internal.py L224 
[2023-11-09 17:07:50,712] INFO _log() L224   * Restarting with stat - call_trace=C:\Users\talit\AppData\Local\Programs\Python\Python311\Lib\site-packages\werkzeug\_internal.py L224 
[2023-11-09 17:08:55,815] INFO _log() L224   * Detected change in 'C:\\fabrica\\pessoal\\pos-full-stack\\mvp\\first-sprint\\back-end\\app.py', reloading - call_trace=C:\Users\talit\AppData\Local\Programs\Python\Python311\Lib\site-packages\werkzeug\_internal.py L224 
[2023-11-09 17:08:55,914] INFO _log() L224   * Restarting with stat - call_trace=C:\Users\talit\AppData\Local\Programs\Python\Python311\Lib\site-packages\werkzeug\_internal.py L224 
[2023-11-09 17:09:15,482] INFO _log() L224   * Detected change in 'C:\\fabrica\\pessoal\\pos-full-stack\\mvp\\first-sprint\\back-end\\app.py', reloading - call_trace=C:\Users\talit\AppData\Local\Programs\Python\Python311\Lib\site-packages\werkzeug\_internal.py L224 
[2023-11-09 17:09:15,583] INFO _log() L224   * Restarting with stat - call_trace=C:\Users\talit\AppData\Local\Programs\Python\Python311\Lib\site-packages\werkzeug\_internal.py L224 
[2023-11-09 17:09:23,032] INFO _log() L224   * Detected change in 'C:\\fabrica\\pessoal\\pos-full-stack\\mvp\\first-sprint\\back-end\\app.py', reloading - call_trace=C:\Users\talit\AppData\Local\Programs\Python\Python311\Lib\site-packages\werkzeug\_internal.py L224 
[2023-11-09 17:09:23,132] INFO _log() L224   * Restarting with stat - call_trace=C:\Users\talit\AppData\Local\Programs\Python\Python311\Lib\site-packages\werkzeug\_internal.py L224 
[2023-11-09 17:09:24,800] ERROR log_exception() L1449 Exception on /products [GET] - call_trace=C:\Users\talit\AppData\Local\Programs\Python\Python311\Lib\site-packages\flask\app.py L1449
Traceback (most recent call last):
  File "C:\Users\talit\AppData\Local\Programs\Python\Python311\Lib\site-packages\flask\app.py", line 2073, in wsgi_app
    response = self.full_dispatch_request()
               ^^^^^^^^^^^^^^^^^^^^^^^^^^^^
  File "C:\Users\talit\AppData\Local\Programs\Python\Python311\Lib\site-packages\flask\app.py", line 1520, in full_dispatch_request
    return self.finalize_request(rv)
           ^^^^^^^^^^^^^^^^^^^^^^^^^
  File "C:\Users\talit\AppData\Local\Programs\Python\Python311\Lib\site-packages\flask\app.py", line 1539, in finalize_request
    response = self.make_response(rv)
               ^^^^^^^^^^^^^^^^^^^^^^
  File "C:\Users\talit\AppData\Local\Programs\Python\Python311\Lib\site-packages\flask\app.py", line 1730, in make_response
    raise TypeError(
TypeError: The view function did not return a valid response. The return type must be a string, dict, tuple, Response instance, or WSGI callable, but it was a list.
[2023-11-09 17:09:24,805] INFO _log() L224  127.0.0.1 - - [09/Nov/2023 17:09:24] "[35m[1mGET /products HTTP/1.1[0m" 500 - - call_trace=C:\Users\talit\AppData\Local\Programs\Python\Python311\Lib\site-packages\werkzeug\_internal.py L224 
[2023-11-09 17:10:05,090] ERROR log_exception() L1449 Exception on /products [GET] - call_trace=C:\Users\talit\AppData\Local\Programs\Python\Python311\Lib\site-packages\flask\app.py L1449
Traceback (most recent call last):
  File "C:\Users\talit\AppData\Local\Programs\Python\Python311\Lib\site-packages\flask\app.py", line 2073, in wsgi_app
    response = self.full_dispatch_request()
               ^^^^^^^^^^^^^^^^^^^^^^^^^^^^
  File "C:\Users\talit\AppData\Local\Programs\Python\Python311\Lib\site-packages\flask\app.py", line 1520, in full_dispatch_request
    return self.finalize_request(rv)
           ^^^^^^^^^^^^^^^^^^^^^^^^^
  File "C:\Users\talit\AppData\Local\Programs\Python\Python311\Lib\site-packages\flask\app.py", line 1539, in finalize_request
    response = self.make_response(rv)
               ^^^^^^^^^^^^^^^^^^^^^^
  File "C:\Users\talit\AppData\Local\Programs\Python\Python311\Lib\site-packages\flask\app.py", line 1730, in make_response
    raise TypeError(
TypeError: The view function did not return a valid response. The return type must be a string, dict, tuple, Response instance, or WSGI callable, but it was a list.
[2023-11-09 17:10:05,092] INFO _log() L224  127.0.0.1 - - [09/Nov/2023 17:10:05] "[35m[1mGET /products HTTP/1.1[0m" 500 - - call_trace=C:\Users\talit\AppData\Local\Programs\Python\Python311\Lib\site-packages\werkzeug\_internal.py L224 
[2023-11-09 17:30:30,228] INFO _log() L224   * Detected change in 'C:\\fabrica\\pessoal\\pos-full-stack\\mvp\\first-sprint\\back-end\\app.py', reloading - call_trace=C:\Users\talit\AppData\Local\Programs\Python\Python311\Lib\site-packages\werkzeug\_internal.py L224 
[2023-11-09 17:30:30,335] INFO _log() L224   * Restarting with stat - call_trace=C:\Users\talit\AppData\Local\Programs\Python\Python311\Lib\site-packages\werkzeug\_internal.py L224 
[2023-11-09 17:31:54,646] INFO _log() L224  [31m[1mWARNING: This is a development server. Do not use it in a production deployment. Use a production WSGI server instead.[0m
 * Running on all addresses (0.0.0.0)
 * Running on http://127.0.0.1:5000
 * Running on http://192.168.0.58:5000 - call_trace=C:\Users\talit\AppData\Local\Programs\Python\Python311\Lib\site-packages\werkzeug\_internal.py L224 
[2023-11-09 17:31:54,646] INFO _log() L224  [33mPress CTRL+C to quit[0m - call_trace=C:\Users\talit\AppData\Local\Programs\Python\Python311\Lib\site-packages\werkzeug\_internal.py L224 
[2023-11-09 17:31:54,646] INFO _log() L224   * Restarting with stat - call_trace=C:\Users\talit\AppData\Local\Programs\Python\Python311\Lib\site-packages\werkzeug\_internal.py L224 
[2023-11-09 17:31:57,662] INFO _log() L224  127.0.0.1 - - [09/Nov/2023 17:31:57] "[32mGET / HTTP/1.1[0m" 302 - - call_trace=C:\Users\talit\AppData\Local\Programs\Python\Python311\Lib\site-packages\werkzeug\_internal.py L224 
