[2023-11-09 17:39:31,147] INFO _log() L224   * Restarting with stat - call_trace=C:\Users\talit\AppData\Local\Programs\Python\Python311\Lib\site-packages\werkzeug\_internal.py L224 
[2023-11-09 17:39:33,090] INFO _log() L224  127.0.0.1 - - [09/Nov/2023 17:39:33] "GET /products HTTP/1.1" 200 - - call_trace=C:\Users\talit\AppData\Local\Programs\Python\Python311\Lib\site-packages\werkzeug\_internal.py L224 
[2023-11-09 17:39:38,667] INFO _log() L224  127.0.0.1 - - [09/Nov/2023 17:39:38] "GET /products HTTP/1.1" 200 - - call_trace=C:\Users\talit\AppData\Local\Programs\Python\Python311\Lib\site-packages\werkzeug\_internal.py L224 
[2023-11-09 17:39:52,811] INFO _log() L224   * Detected change in 'C:\\fabrica\\pessoal\\pos-full-stack\\mvp\\first-sprint\\back-end\\schemas\\product.py', reloading - call_trace=C:\Users\talit\AppData\Local\Programs\Python\Python311\Lib\site-packages\werkzeug\_internal.py L224 
[2023-11-09 17:39:52,944] INFO _log() L224   * Restarting with stat - call_trace=C:\Users\talit\AppData\Local\Programs\Python\Python311\Lib\site-packages\werkzeug\_internal.py L224 
[2023-11-09 17:39:54,735] ERROR log_exception() L1449 Exception on /products [GET] - call_trace=C:\Users\talit\AppData\Local\Programs\Python\Python311\Lib\site-packages\flask\app.py L1449
Traceback (most recent call last):
  File "C:\Users\talit\AppData\Local\Programs\Python\Python311\Lib\site-packages\flask\app.py", line 2073, in wsgi_app
    response = self.full_dispatch_request()
               ^^^^^^^^^^^^^^^^^^^^^^^^^^^^
  File "C:\Users\talit\AppData\Local\Programs\Python\Python311\Lib\site-packages\flask\app.py", line 1520, in full_dispatch_request
    return self.finalize_request(rv)
           ^^^^^^^^^^^^^^^^^^^^^^^^^
  File "C:\Users\talit\AppData\Local\Programs\Python\Python311\Lib\site-packages\flask\app.py", line 1539, in finalize_request
    response = self.make_response(rv)
               ^^^^^^^^^^^^^^^^^^^^^^
  File "C:\Users\talit\AppData\Local\Programs\Python\Python311\Lib\site-packages\flask\app.py", line 1730, in make_response
    raise TypeError(
TypeError: The view function did not return a valid response. The return type must be a string, dict, tuple, Response instance, or WSGI callable, but it was a list.
[2023-11-09 17:39:54,739] INFO _log() L224  127.0.0.1 - - [09/Nov/2023 17:39:54] "[35m[1mGET /products HTTP/1.1[0m" 500 - - call_trace=C:\Users\talit\AppData\Local\Programs\Python\Python311\Lib\site-packages\werkzeug\_internal.py L224 
[2023-11-09 17:40:37,824] INFO _log() L224   * Detected change in 'C:\\fabrica\\pessoal\\pos-full-stack\\mvp\\first-sprint\\back-end\\schemas\\product.py', reloading - call_trace=C:\Users\talit\AppData\Local\Programs\Python\Python311\Lib\site-packages\werkzeug\_internal.py L224 
[2023-11-09 17:40:37,980] INFO _log() L224   * Restarting with stat - call_trace=C:\Users\talit\AppData\Local\Programs\Python\Python311\Lib\site-packages\werkzeug\_internal.py L224 
[2023-11-09 17:40:40,437] INFO _log() L224  127.0.0.1 - - [09/Nov/2023 17:40:40] "[35m[1mGET /products HTTP/1.1[0m" 500 - - call_trace=C:\Users\talit\AppData\Local\Programs\Python\Python311\Lib\site-packages\werkzeug\_internal.py L224 
[2023-11-09 17:40:40,448] ERROR _log() L224  Error on request:
Traceback (most recent call last):
  File "C:\Users\talit\AppData\Local\Programs\Python\Python311\Lib\site-packages\werkzeug\serving.py", line 335, in run_wsgi
    execute(self.server.app)
  File "C:\Users\talit\AppData\Local\Programs\Python\Python311\Lib\site-packages\werkzeug\serving.py", line 322, in execute
    application_iter = app(environ, start_response)
                       ^^^^^^^^^^^^^^^^^^^^^^^^^^^^
flask.cli.NoAppException: While importing 'app', an ImportError was raised:

Traceback (most recent call last):
  File "C:\Users\talit\AppData\Local\Programs\Python\Python311\Lib\site-packages\flask\cli.py", line 214, in locate_app
    __import__(module_name)
  File "C:\fabrica\pessoal\pos-full-stack\mvp\first-sprint\back-end\app.py", line 11, in <module>
    from schemas import *
  File "C:\fabrica\pessoal\pos-full-stack\mvp\first-sprint\back-end\schemas\__init__.py", line 2, in <module>
    from schemas.product import ProductSchema, ProductBuscaSchema, ProductViewSchema, \
ImportError: cannot import name 'apresenta_products' from 'schemas.product' (C:\fabrica\pessoal\pos-full-stack\mvp\first-sprint\back-end\schemas\product.py) - call_trace=C:\Users\talit\AppData\Local\Programs\Python\Python311\Lib\site-packages\werkzeug\_internal.py L224 
[2023-11-09 17:40:48,471] INFO _log() L224   * Detected change in 'C:\\fabrica\\pessoal\\pos-full-stack\\mvp\\first-sprint\\back-end\\schemas\\product.py', reloading - call_trace=C:\Users\talit\AppData\Local\Programs\Python\Python311\Lib\site-packages\werkzeug\_internal.py L224 
[2023-11-09 17:40:48,594] INFO _log() L224   * Restarting with stat - call_trace=C:\Users\talit\AppData\Local\Programs\Python\Python311\Lib\site-packages\werkzeug\_internal.py L224 
[2023-11-09 17:43:07,518] INFO _log() L224   * Detected change in 'C:\\fabrica\\pessoal\\pos-full-stack\\mvp\\first-sprint\\back-end\\schemas\\product.py', reloading - call_trace=C:\Users\talit\AppData\Local\Programs\Python\Python311\Lib\site-packages\werkzeug\_internal.py L224 
[2023-11-09 17:43:07,641] INFO _log() L224   * Restarting with stat - call_trace=C:\Users\talit\AppData\Local\Programs\Python\Python311\Lib\site-packages\werkzeug\_internal.py L224 
[2023-11-09 17:43:12,210] ERROR log_exception() L1449 Exception on /products [GET] - call_trace=C:\Users\talit\AppData\Local\Programs\Python\Python311\Lib\site-packages\flask\app.py L1449
Traceback (most recent call last):
  File "C:\Users\talit\AppData\Local\Programs\Python\Python311\Lib\site-packages\flask\app.py", line 2073, in wsgi_app
    response = self.full_dispatch_request()
               ^^^^^^^^^^^^^^^^^^^^^^^^^^^^
  File "C:\Users\talit\AppData\Local\Programs\Python\Python311\Lib\site-packages\flask\app.py", line 1520, in full_dispatch_request
    return self.finalize_request(rv)
           ^^^^^^^^^^^^^^^^^^^^^^^^^
  File "C:\Users\talit\AppData\Local\Programs\Python\Python311\Lib\site-packages\flask\app.py", line 1539, in finalize_request
    response = self.make_response(rv)
               ^^^^^^^^^^^^^^^^^^^^^^
  File "C:\Users\talit\AppData\Local\Programs\Python\Python311\Lib\site-packages\flask\app.py", line 1730, in make_response
    raise TypeError(
TypeError: The view function did not return a valid response. The return type must be a string, dict, tuple, Response instance, or WSGI callable, but it was a list.
[2023-11-09 17:43:12,214] INFO _log() L224  127.0.0.1 - - [09/Nov/2023 17:43:12] "[35m[1mGET /products HTTP/1.1[0m" 500 - - call_trace=C:\Users\talit\AppData\Local\Programs\Python\Python311\Lib\site-packages\werkzeug\_internal.py L224 
[2023-11-09 17:43:40,409] INFO _log() L224   * Detected change in 'C:\\fabrica\\pessoal\\pos-full-stack\\mvp\\first-sprint\\back-end\\schemas\\product.py', reloading - call_trace=C:\Users\talit\AppData\Local\Programs\Python\Python311\Lib\site-packages\werkzeug\_internal.py L224 
[2023-11-09 17:43:40,535] INFO _log() L224   * Restarting with stat - call_trace=C:\Users\talit\AppData\Local\Programs\Python\Python311\Lib\site-packages\werkzeug\_internal.py L224 
[2023-11-09 17:44:27,427] INFO _log() L224   * Detected change in 'C:\\fabrica\\pessoal\\pos-full-stack\\mvp\\first-sprint\\back-end\\app.py', reloading - call_trace=C:\Users\talit\AppData\Local\Programs\Python\Python311\Lib\site-packages\werkzeug\_internal.py L224 
[2023-11-09 17:44:27,554] INFO _log() L224   * Restarting with stat - call_trace=C:\Users\talit\AppData\Local\Programs\Python\Python311\Lib\site-packages\werkzeug\_internal.py L224 
[2023-11-09 17:44:30,931] INFO _log() L224  127.0.0.1 - - [09/Nov/2023 17:44:30] "[35m[1mGET /products HTTP/1.1[0m" 500 - - call_trace=C:\Users\talit\AppData\Local\Programs\Python\Python311\Lib\site-packages\werkzeug\_internal.py L224 
[2023-11-09 17:44:30,942] ERROR _log() L224  Error on request:
Traceback (most recent call last):
  File "C:\Users\talit\AppData\Local\Programs\Python\Python311\Lib\site-packages\werkzeug\serving.py", line 335, in run_wsgi
    execute(self.server.app)
  File "C:\Users\talit\AppData\Local\Programs\Python\Python311\Lib\site-packages\werkzeug\serving.py", line 322, in execute
    application_iter = app(environ, start_response)
                       ^^^^^^^^^^^^^^^^^^^^^^^^^^^^
flask.cli.NoAppException: While importing 'app', an ImportError was raised:

Traceback (most recent call last):
  File "C:\Users\talit\AppData\Local\Programs\Python\Python311\Lib\site-packages\flask\cli.py", line 214, in locate_app
    __import__(module_name)
  File "C:\fabrica\pessoal\pos-full-stack\mvp\first-sprint\back-end\app.py", line 11, in <module>
    from schemas import *
  File "C:\fabrica\pessoal\pos-full-stack\mvp\first-sprint\back-end\schemas\__init__.py", line 2, in <module>
    from schemas.product import ProductSchema, ProductBuscaSchema, ProductViewSchema, \
ImportError: cannot import name 'apresenta_products' from 'schemas.product' (C:\fabrica\pessoal\pos-full-stack\mvp\first-sprint\back-end\schemas\product.py) - call_trace=C:\Users\talit\AppData\Local\Programs\Python\Python311\Lib\site-packages\werkzeug\_internal.py L224 
[2023-11-09 17:44:49,122] INFO _log() L224   * Detected change in 'C:\\fabrica\\pessoal\\pos-full-stack\\mvp\\first-sprint\\back-end\\app.py', reloading - call_trace=C:\Users\talit\AppData\Local\Programs\Python\Python311\Lib\site-packages\werkzeug\_internal.py L224 
[2023-11-09 17:44:49,242] INFO _log() L224   * Restarting with stat - call_trace=C:\Users\talit\AppData\Local\Programs\Python\Python311\Lib\site-packages\werkzeug\_internal.py L224 
