[2023-11-09 17:37:19,975] INFO _log() L224   * Restarting with stat - call_trace=C:\Users\talit\AppData\Local\Programs\Python\Python311\Lib\site-packages\werkzeug\_internal.py L224 
[2023-11-09 17:37:22,710] ERROR log_exception() L1449 Exception on /products [GET] - call_trace=C:\Users\talit\AppData\Local\Programs\Python\Python311\Lib\site-packages\flask\app.py L1449
Traceback (most recent call last):
  File "C:\Users\talit\AppData\Local\Programs\Python\Python311\Lib\site-packages\flask\app.py", line 2073, in wsgi_app
    response = self.full_dispatch_request()
               ^^^^^^^^^^^^^^^^^^^^^^^^^^^^
  File "C:\Users\talit\AppData\Local\Programs\Python\Python311\Lib\site-packages\flask\app.py", line 1520, in full_dispatch_request
    return self.finalize_request(rv)
           ^^^^^^^^^^^^^^^^^^^^^^^^^
  File "C:\Users\talit\AppData\Local\Programs\Python\Python311\Lib\site-packages\flask\app.py", line 1539, in finalize_request
    response = self.make_response(rv)
               ^^^^^^^^^^^^^^^^^^^^^^
  File "C:\Users\talit\AppData\Local\Programs\Python\Python311\Lib\site-packages\flask\app.py", line 1730, in make_response
    raise TypeError(
TypeError: The view function did not return a valid response. The return type must be a string, dict, tuple, Response instance, or WSGI callable, but it was a list.
[2023-11-09 17:37:22,713] INFO _log() L224  127.0.0.1 - - [09/Nov/2023 17:37:22] "[35m[1mGET /products HTTP/1.1[0m" 500 - - call_trace=C:\Users\talit\AppData\Local\Programs\Python\Python311\Lib\site-packages\werkzeug\_internal.py L224 
[2023-11-09 17:37:57,765] INFO _log() L224   * Detected change in 'C:\\fabrica\\pessoal\\pos-full-stack\\mvp\\first-sprint\\back-end\\schemas\\product.py', reloading - call_trace=C:\Users\talit\AppData\Local\Programs\Python\Python311\Lib\site-packages\werkzeug\_internal.py L224 
[2023-11-09 17:37:57,909] INFO _log() L224   * Restarting with stat - call_trace=C:\Users\talit\AppData\Local\Programs\Python\Python311\Lib\site-packages\werkzeug\_internal.py L224 
[2023-11-09 17:38:03,195] INFO _log() L224  127.0.0.1 - - [09/Nov/2023 17:38:03] "GET /products HTTP/1.1" 200 - - call_trace=C:\Users\talit\AppData\Local\Programs\Python\Python311\Lib\site-packages\werkzeug\_internal.py L224 
[2023-11-09 17:38:19,546] INFO _log() L224   * Detected change in 'C:\\fabrica\\pessoal\\pos-full-stack\\mvp\\first-sprint\\back-end\\app.py', reloading - call_trace=C:\Users\talit\AppData\Local\Programs\Python\Python311\Lib\site-packages\werkzeug\_internal.py L224 
[2023-11-09 17:38:19,694] INFO _log() L224   * Restarting with stat - call_trace=C:\Users\talit\AppData\Local\Programs\Python\Python311\Lib\site-packages\werkzeug\_internal.py L224 
[2023-11-09 17:38:21,986] ERROR log_exception() L1449 Exception on /products [GET] - call_trace=C:\Users\talit\AppData\Local\Programs\Python\Python311\Lib\site-packages\flask\app.py L1449
Traceback (most recent call last):
  File "C:\Users\talit\AppData\Local\Programs\Python\Python311\Lib\site-packages\flask\app.py", line 2073, in wsgi_app
    response = self.full_dispatch_request()
               ^^^^^^^^^^^^^^^^^^^^^^^^^^^^
  File "C:\Users\talit\AppData\Local\Programs\Python\Python311\Lib\site-packages\flask\app.py", line 1520, in full_dispatch_request
    return self.finalize_request(rv)
           ^^^^^^^^^^^^^^^^^^^^^^^^^
  File "C:\Users\talit\AppData\Local\Programs\Python\Python311\Lib\site-packages\flask\app.py", line 1539, in finalize_request
    response = self.make_response(rv)
               ^^^^^^^^^^^^^^^^^^^^^^
  File "C:\Users\talit\AppData\Local\Programs\Python\Python311\Lib\site-packages\flask\app.py", line 1723, in make_response
    raise TypeError(
  File "C:\Users\talit\AppData\Local\Programs\Python\Python311\Lib\site-packages\flask\app.py", line 1719, in make_response
    rv = self.response_class.force_type(
         ^^^^^^^^^^^^^^^^^^^^^^^^^^^^^^^
  File "C:\Users\talit\AppData\Local\Programs\Python\Python311\Lib\site-packages\werkzeug\wrappers\response.py", line 268, in force_type
    response = Response(*run_wsgi_app(response, environ))
                         ^^^^^^^^^^^^^^^^^^^^^^^^^^^^^^^
  File "C:\Users\talit\AppData\Local\Programs\Python\Python311\Lib\site-packages\werkzeug\test.py", line 1242, in run_wsgi_app
    app_rv = app(environ, start_response)
             ^^^^^^^^^^^^^^^^^^^^^^^^^^^^
TypeError: Response.__call__() missing 1 required positional argument: 'send'
The view function did not return a valid response. The return type must be a string, dict, tuple, Response instance, or WSGI callable, but it was a JSONResponse.
[2023-11-09 17:38:21,992] INFO _log() L224  127.0.0.1 - - [09/Nov/2023 17:38:21] "[35m[1mGET /products HTTP/1.1[0m" 500 - - call_trace=C:\Users\talit\AppData\Local\Programs\Python\Python311\Lib\site-packages\werkzeug\_internal.py L224 
[2023-11-09 17:38:41,346] INFO _log() L224   * Detected change in 'C:\\fabrica\\pessoal\\pos-full-stack\\mvp\\first-sprint\\back-end\\app.py', reloading - call_trace=C:\Users\talit\AppData\Local\Programs\Python\Python311\Lib\site-packages\werkzeug\_internal.py L224 
[2023-11-09 17:38:41,507] INFO _log() L224   * Restarting with stat - call_trace=C:\Users\talit\AppData\Local\Programs\Python\Python311\Lib\site-packages\werkzeug\_internal.py L224 
[2023-11-09 17:38:43,680] ERROR log_exception() L1449 Exception on /products [GET] - call_trace=C:\Users\talit\AppData\Local\Programs\Python\Python311\Lib\site-packages\flask\app.py L1449
Traceback (most recent call last):
  File "C:\Users\talit\AppData\Local\Programs\Python\Python311\Lib\site-packages\flask\app.py", line 2073, in wsgi_app
    response = self.full_dispatch_request()
               ^^^^^^^^^^^^^^^^^^^^^^^^^^^^
  File "C:\Users\talit\AppData\Local\Programs\Python\Python311\Lib\site-packages\flask\app.py", line 1520, in full_dispatch_request
    return self.finalize_request(rv)
           ^^^^^^^^^^^^^^^^^^^^^^^^^
  File "C:\Users\talit\AppData\Local\Programs\Python\Python311\Lib\site-packages\flask\app.py", line 1539, in finalize_request
    response = self.make_response(rv)
               ^^^^^^^^^^^^^^^^^^^^^^
  File "C:\Users\talit\AppData\Local\Programs\Python\Python311\Lib\site-packages\flask\app.py", line 1723, in make_response
    raise TypeError(
  File "C:\Users\talit\AppData\Local\Programs\Python\Python311\Lib\site-packages\flask\app.py", line 1719, in make_response
    rv = self.response_class.force_type(
         ^^^^^^^^^^^^^^^^^^^^^^^^^^^^^^^
  File "C:\Users\talit\AppData\Local\Programs\Python\Python311\Lib\site-packages\werkzeug\wrappers\response.py", line 268, in force_type
    response = Response(*run_wsgi_app(response, environ))
                         ^^^^^^^^^^^^^^^^^^^^^^^^^^^^^^^
  File "C:\Users\talit\AppData\Local\Programs\Python\Python311\Lib\site-packages\werkzeug\test.py", line 1242, in run_wsgi_app
    app_rv = app(environ, start_response)
             ^^^^^^^^^^^^^^^^^^^^^^^^^^^^
TypeError: Response.__call__() missing 1 required positional argument: 'send'
The view function did not return a valid response. The return type must be a string, dict, tuple, Response instance, or WSGI callable, but it was a JSONResponse.
[2023-11-09 17:38:43,684] INFO _log() L224  127.0.0.1 - - [09/Nov/2023 17:38:43] "[35m[1mGET /products HTTP/1.1[0m" 500 - - call_trace=C:\Users\talit\AppData\Local\Programs\Python\Python311\Lib\site-packages\werkzeug\_internal.py L224 
[2023-11-09 17:39:03,168] INFO _log() L224   * Detected change in 'C:\\fabrica\\pessoal\\pos-full-stack\\mvp\\first-sprint\\back-end\\app.py', reloading - call_trace=C:\Users\talit\AppData\Local\Programs\Python\Python311\Lib\site-packages\werkzeug\_internal.py L224 
[2023-11-09 17:39:03,302] INFO _log() L224   * Restarting with stat - call_trace=C:\Users\talit\AppData\Local\Programs\Python\Python311\Lib\site-packages\werkzeug\_internal.py L224 
[2023-11-09 17:39:04,622] ERROR log_exception() L1449 Exception on /products [GET] - call_trace=C:\Users\talit\AppData\Local\Programs\Python\Python311\Lib\site-packages\flask\app.py L1449
Traceback (most recent call last):
  File "C:\Users\talit\AppData\Local\Programs\Python\Python311\Lib\site-packages\flask\app.py", line 2073, in wsgi_app
    response = self.full_dispatch_request()
               ^^^^^^^^^^^^^^^^^^^^^^^^^^^^
  File "C:\Users\talit\AppData\Local\Programs\Python\Python311\Lib\site-packages\flask\app.py", line 1520, in full_dispatch_request
    return self.finalize_request(rv)
           ^^^^^^^^^^^^^^^^^^^^^^^^^
  File "C:\Users\talit\AppData\Local\Programs\Python\Python311\Lib\site-packages\flask\app.py", line 1539, in finalize_request
    response = self.make_response(rv)
               ^^^^^^^^^^^^^^^^^^^^^^
  File "C:\Users\talit\AppData\Local\Programs\Python\Python311\Lib\site-packages\flask\app.py", line 1723, in make_response
    raise TypeError(
  File "C:\Users\talit\AppData\Local\Programs\Python\Python311\Lib\site-packages\flask\app.py", line 1719, in make_response
    rv = self.response_class.force_type(
         ^^^^^^^^^^^^^^^^^^^^^^^^^^^^^^^
  File "C:\Users\talit\AppData\Local\Programs\Python\Python311\Lib\site-packages\werkzeug\wrappers\response.py", line 268, in force_type
    response = Response(*run_wsgi_app(response, environ))
                         ^^^^^^^^^^^^^^^^^^^^^^^^^^^^^^^
  File "C:\Users\talit\AppData\Local\Programs\Python\Python311\Lib\site-packages\werkzeug\test.py", line 1242, in run_wsgi_app
    app_rv = app(environ, start_response)
             ^^^^^^^^^^^^^^^^^^^^^^^^^^^^
TypeError: Response.__call__() missing 1 required positional argument: 'send'
The view function did not return a valid response. The return type must be a string, dict, tuple, Response instance, or WSGI callable, but it was a JSONResponse.
