[2023-11-09 17:45:31,242] INFO _log() L224   * Restarting with stat - call_trace=C:\Users\talit\AppData\Local\Programs\Python\Python311\Lib\site-packages\werkzeug\_internal.py L224 
[2023-11-09 17:45:40,059] INFO _log() L224  127.0.0.1 - - [09/Nov/2023 17:45:40] "[35m[1mGET /products HTTP/1.1[0m" 500 - - call_trace=C:\Users\talit\AppData\Local\Programs\Python\Python311\Lib\site-packages\werkzeug\_internal.py L224 
[2023-11-09 17:45:40,067] ERROR _log() L224  Error on request:
Traceback (most recent call last):
  File "C:\Users\talit\AppData\Local\Programs\Python\Python311\Lib\site-packages\werkzeug\serving.py", line 335, in run_wsgi
    execute(self.server.app)
  File "C:\Users\talit\AppData\Local\Programs\Python\Python311\Lib\site-packages\werkzeug\serving.py", line 322, in execute
    application_iter = app(environ, start_response)
                       ^^^^^^^^^^^^^^^^^^^^^^^^^^^^
  File "C:\fabrica\pessoal\pos-full-stack\mvp\first-sprint\back-end\app.py", line 36, in <module>
    responses={"200": ProductViewSchema, "409": ErrorSchema, "400": ErrorSchema},
                      ^^^^^^^^^^^^^^^^^^^^^^^^^^^^^^^^^^^^^^^^^^^^^^^^^^^^^^^^^^^
NameError: name 'ProductViewSchema' is not defined - call_trace=C:\Users\talit\AppData\Local\Programs\Python\Python311\Lib\site-packages\werkzeug\_internal.py L224 
[2023-11-09 17:46:02,977] INFO _log() L224   * Detected change in 'C:\\fabrica\\pessoal\\pos-full-stack\\mvp\\first-sprint\\back-end\\schemas\\__init__.py', reloading - call_trace=C:\Users\talit\AppData\Local\Programs\Python\Python311\Lib\site-packages\werkzeug\_internal.py L224 
[2023-11-09 17:46:03,096] INFO _log() L224   * Restarting with stat - call_trace=C:\Users\talit\AppData\Local\Programs\Python\Python311\Lib\site-packages\werkzeug\_internal.py L224 
